Workbook
Name NativeTimeline_fixed_OD: #N/A
Name Slicer_Region4: #N/A

Sheet global_data
A1: Order ID | B1: fixed_OD | C1: Salesperson ID | D1: Salesperson Name | E1: Region | F1: City | G1: Product ID | H1: Product Name | I1: Category | J1: Unit Price | K1: Quantity | L1: Discount | M1: Revenue | N1: Payment Mode | O1: Order Status | P1: R/D | Q1: Check overdiscounting | R1: Original revenue | S1: revenue lost due to discount | T1: average order value
A2: ORD01215 | B2: 45456 | C2: SP03 | D2: Ravi Kumar | E2: East | F2: Kolkata | G2: PRD015 | H2: Dettol Liquid Soap 250ml | I2: Personal Care | J2: 145 | K2: 12 | L2: 0.11 | M2: 1548.6 | N2: Net Banking | O2: Delivered | P2: =global_data!$M2/global_data!$L2 -> 14078.182 | Q2: =IFERROR(global_data!$P2,0) -> 14078.182 | R2: =global_data!$M2/(1-global_data!$L2) -> 1740 | S2: =global_data!$R2-global_data!$M2 -> 191.4
A3: ORD01250 | B3: 45548 | C3: SP012 | D3: Sneha Patil | E3: West | F3: Ahmedabad | G3: PRD005 | H3: Bajaj Mixer Grinder 750W | I3: Appliances | J3: 2100 | K3: 17 | L3: 0.06 | M3: 33558 | N3: Debit Card | O3: Pending | P3: =global_data!$M3/global_data!$L3 -> 559300 | Q3: =IFERROR(global_data!$P3,0) -> 559300 | R3: =global_data!$M3/(1-global_data!$L3) -> 35700 | S3: =global_data!$R3-global_data!$M3 -> 2142
A4: ORD01262 | B4: 45552 | C4: SP05 | D4: Suresh Pillai | E4: South | F4: Hyderabad | G4: PRD019 | H4: Classmate A4 Notebook 200pg | I4: Stationery | J4: 85 | K4: 20 | L4: 0.03 | M4: 1649 | N4: EMI | O4: Delivered | P4: =global_data!$M4/global_data!$L4 -> 54966.667 | Q4: =IFERROR(global_data!$P4,0) -> 54966.667 | R4: =global_data!$M4/(1-global_data!$L4) -> 1700 | S4: =global_data!$R4-global_data!$M4 -> 51
A5: ORD01301 | B5: 45445 | C5: SP011 | D5: Nikhil Joshi | E5: East | F5: Kolkata | G5: PRD008 | H5: American Tourister Trolley | I5: Bags | J5: 4999 | K5: 3 | L5: 0.21 | M5: 11847.63 | N5: Debit Card | O5: Delivered | P5: =global_data!$M5/global_data!$L5 -> 56417.286 | Q5: =IFERROR(global_data!$P5,0) -> 56417.286 | R5: =global_data!$M5/(1-global_data!$L5) -> 14997 | S5: =global_data!$R5-global_data!$M5 -> 3149.37
A6: ORD01373 | B6: 45433 | C6: SP011 | D6: Nikhil Joshi | E6: East | F6: Ranchi | G6: PRD010 | H6: Bata Ladies Sandals | I6: Footwear | J6: 1299 | K6: 7 | L6: 0.16 | M6: 7638.12 | N6: Debit Card | O6: Delivered | P6: =global_data!$M6/global_data!$L6 -> 47738.25 | Q6: =IFERROR(global_data!$P6,0) -> 47738.25 | R6: =global_data!$M6/(1-global_data!$L6) -> 9093 | S6: =global_data!$R6-global_data!$M6 -> 1454.88
A7: ORD01411 | B7: 45317 | C7: SP07 | D7: Rohit Verma | E7: East | F7: Ranchi | G7: PRD009 | H7: Woodland Men Boots | I7: Footwear | J7: 3499 | K7: 6 | L7: 0.01 | M7: 20784.06 | N7: Credit Card | O7: Delivered | P7: =global_data!$M7/global_data!$L7 -> 2078406 | Q7: =IFERROR(global_data!$P7,0) -> 2078406 | R7: =global_data!$M7/(1-global_data!$L7) -> 20994 | S7: =global_data!$R7-global_data!$M7 -> 209.94
A8: ORD01523 | B8: 45592 | C8: SP08 | D8: Kavitha Reddy | E8: West | F8: Ahmedabad | G8: PRD005 | H8: Bajaj Mixer Grinder 750W | I8: Appliances | J8: 2100 | K8: 2 | L8: 0.05 | M8: 3990 | N8: EMI | O8: Delivered | P8: =global_data!$M8/global_data!$L8 -> 79800 | Q8: =IFERROR(global_data!$P8,0) -> 79800 | R8: =global_data!$M8/(1-global_data!$L8) -> 4200 | S8: =global_data!$R8-global_data!$M8 -> 210
A9: ORD01674 | B9: 45374 | C9: SP04 | D9: Fatima Sheikh | E9: West | F9: Nagpur | G9: PRD018 | H9: Maggi Noodles Pack of 12 | I9: Food & Bev | J9: 144 | K9: 17 | L9: 0.23 | M9: 1884.96 | N9: EMI | O9: Delivered | P9: =global_data!$M9/global_data!$L9 -> 8195.4783 | Q9: =IFERROR(global_data!$P9,0) -> 8195.4783 | R9: =global_data!$M9/(1-global_data!$L9) -> 2448 | S9: =global_data!$R9-global_data!$M9 -> 563.04
A10: ORD01777 | B10: 45623 | C10: SP05 | D10: Suresh Pillai | E10: South | F10: Coimbatore | G10: PRD009 | H10: Woodland Men Boots | I10: Footwear | J10: 3499 | K10: 7 | L10: 0.01 | M10: 24248.07 | N10: Net Banking | O10: Delivered | P10: =global_data!$M10/global_data!$L10 -> 2424807 | Q10: =IFERROR(global_data!$P10,0) -> 2424807 | R10: =global_data!$M10/(1-global_data!$L10) -> 24493 | S10: =global_data!$R10-global_data!$M10 -> 244.93
A11: ORD01846 | B11: 45563 | C11: SP010 | D11: Divya Iyer | E11: South | F11: Hyderabad | G11: PRD017 | H11: Tata Gold Tea 500g | I11: Food & Bev | J11: 299 | K11: 8 | L11: 0.23 | M11: 1841.84 | N11: Cash | O11: Delivered | P11: =global_data!$M11/global_data!$L11 -> 8008 | Q11: =IFERROR(global_data!$P11,0) -> 8008 | R11: =global_data!$M11/(1-global_data!$L11) -> 2392 | S11: =global_data!$R11-global_data!$M11 -> 550.16
A12: ORD01850 | B12: 45378 | C12: SP07 | D12: Rohit Verma | E12: East | F12: Guwahati | G12: PRD015 | H12: Dettol Liquid Soap 250ml | I12: Personal Care | J12: 145 | K12: 10 | L12: 0.05 | M12: 1377.5 | N12: Debit Card | O12: Returned | P12: =global_data!$M12/global_data!$L12 -> 27550 | Q12: =IFERROR(global_data!$P12,0) -> 27550 | R12: =global_data!$M12/(1-global_data!$L12) -> 1450 | S12: =global_data!$R12-global_data!$M12 -> 72.5
A13: ORD01904 | B13: 45619 | C13: SP07 | D13: Rohit Verma | E13: East | F13: Ranchi | G13: PRD009 | H13: Woodland Men Boots | I13: Footwear | J13: 3499 | K13: 20 | L13: 0.15 | M13: 59483 | N13: Cash | O13: Delivered | P13: =global_data!$M13/global_data!$L13 -> 396553.33 | Q13: =IFERROR(global_data!$P13,0) -> 396553.33 | R13: =global_data!$M13/(1-global_data!$L13) -> 69980 | S13: =global_data!$R13-global_data!$M13 -> 10497
... A2401: ORD03383 | B2401: 45444 | C2401: SP06 | D2401: Anjali Mehta | E2401: North | F2401: Agra | G2401: PRD009 | H2401: Woodland Men Boots | I2401: Footwear | J2401: 3499 | K2401: 11 | L2401: 0.29 | M2401: 27327.19 | N2401: Cash | O2401: Delivered | P2401: =global_data!$M2401/global_data!$L2401 -> 94231.69 | Q2401: =IFERROR(global_data!$P2401,0) -> 94231.69 | R2401: =global_data!$M2401/(1-global_data!$L2401) -> 38489 | S2401: =global_data!$R2401-global_data!$M2401 -> 11161.81

Sheet Sheet1
A1: Order ID | B1: fixed_OD | C1: Salesperson ID | D1: Salesperson Name | E1: Region | F1: City | G1: Product ID | H1: Product Name | I1: Category | J1: Unit Price | K1: Quantity | L1: Discount | M1: Revenue | N1: Payment Mode | O1: Order Status
A2: ORD01215 | B2: 45456 | C2: SP03 | D2: Ravi Kumar | E2: East | F2: Kolkata | G2: PRD015 | H2: Dettol Liquid Soap 250ml | I2: Personal Care | J2: 145 | K2: 12 | L2: 0.11 | M2: 1548.6 | N2: Net Banking | O2: Delivered
A3: ORD01250 | B3: 45548 | C3: SP012 | D3: Sneha Patil | E3: West | F3: Ahmedabad | G3: PRD005 | H3: Bajaj Mixer Grinder 750W | I3: Appliances | J3: 2100 | K3: 17 | L3: 0.06 | M3: 33558 | N3: Debit Card | O3: Pending
A4: ORD01262 | B4: 45552 | C4: SP05 | D4: Suresh Pillai | E4: South | F4: Hyderabad | G4: PRD019 | H4: Classmate A4 Notebook 200pg | I4: Stationery | J4: 85 | K4: 20 | L4: 0.03 | M4: 1649 | N4: EMI | O4: Delivered
A5: ORD01301 | B5: 45445 | C5: SP011 | D5: Nikhil Joshi | E5: East | F5: Kolkata | G5: PRD008 | H5: American Tourister Trolley | I5: Bags | J5: 4999 | K5: 3 | L5: 0.21 | M5: 11847.63 | N5: Debit Card | O5: Delivered
A6: ORD01373 | B6: 45433 | C6: SP011 | D6: Nikhil Joshi | E6: East | F6: Ranchi | G6: PRD010 | H6: Bata Ladies Sandals | I6: Footwear | J6: 1299 | K6: 7 | L6: 0.16 | M6: 7638.12 | N6: Debit Card | O6: Delivered
A7: ORD01411 | B7: 45317 | C7: SP07 | D7: Rohit Verma | E7: East | F7: Ranchi | G7: PRD009 | H7: Woodland Men Boots | I7: Footwear | J7: 3499 | K7: 6 | L7: 0.01 | M7: 20784.06 | N7: Credit Card | O7: Delivered
A8: ORD01523 | B8: 45592 | C8: SP08 | D8: Kavitha Reddy | E8: West | F8: Ahmedabad | G8: PRD005 | H8: Bajaj Mixer Grinder 750W | I8: Appliances | J8: 2100 | K8: 2 | L8: 0.05 | M8: 3990 | N8: EMI | O8: Delivered
A9: ORD01674 | B9: 45374 | C9: SP04 | D9: Fatima Sheikh | E9: West | F9: Nagpur | G9: PRD018 | H9: Maggi Noodles Pack of 12 | I9: Food & Bev | J9: 144 | K9: 17 | L9: 0.23 | M9: 1884.96 | N9: EMI | O9: Delivered
A10: ORD01777 | B10: 45623 | C10: SP05 | D10: Suresh Pillai | E10: South | F10: Coimbatore | G10: PRD009 | H10: Woodland Men Boots | I10: Footwear | J10: 3499 | K10: 7 | L10: 0.01 | M10: 24248.07 | N10: Net Banking | O10: Delivered
A11: ORD01846 | B11: 45563 | C11: SP010 | D11: Divya Iyer | E11: South | F11: Hyderabad | G11: PRD017 | H11: Tata Gold Tea 500g | I11: Food & Bev | J11: 299 | K11: 8 | L11: 0.23 | M11: 1841.84 | N11: Cash | O11: Delivered
A12: ORD01850 | B12: 45378 | C12: SP07 | D12: Rohit Verma | E12: East | F12: Guwahati | G12: PRD015 | H12: Dettol Liquid Soap 250ml | I12: Personal Care | J12: 145 | K12: 10 | L12: 0.05 | M12: 1377.5 | N12: Debit Card | O12: Returned
A13: ORD01904 | B13: 45619 | C13: SP07 | D13: Rohit Verma | E13: East | F13: Ranchi | G13: PRD009 | H13: Woodland Men Boots | I13: Footwear | J13: 3499 | K13: 20 | L13: 0.15 | M13: 59483 | N13: Cash | O13: Delivered
... A2401: ORD03383 | B2401: 45444 | C2401: SP06 | D2401: Anjali Mehta | E2401: North | F2401: Agra | G2401: PRD009 | H2401: Woodland Men Boots | I2401: Footwear | J2401: 3499 | K2401: 11 | L2401: 0.29 | M2401: 27327.19 | N2401: Cash | O2401: Delivered

Sheet Sheet2
A1: Order ID | B1: fixed_OD | C1: Salesperson ID | D1: Salesperson Name | E1: Region | F1: City | G1: Product ID | H1: Product Name | I1: Category | J1: Unit Price | K1: Quantity | L1: Discount | M1: Revenue | N1: Payment Mode | O1: Order Status | P1: R/D | Q1: Check overdiscounting | R1: Original revenue | S1: revenue lost due to discount
A2: ORD01215 | B2: 45456 | C2: SP03 | D2: Ravi Kumar | E2: East | F2: Kolkata | G2: PRD015 | H2: Dettol Liquid Soap 250ml | I2: Personal Care | J2: 145 | K2: 12 | L2: 0.11 | M2: 1548.6 | N2: Net Banking | O2: Delivered | P2: 14078.182 | Q2: 14078.182 | R2: 1740 | S2: 191.4
A3: ORD01250 | B3: 45548 | C3: SP012 | D3: Sneha Patil | E3: West | F3: Ahmedabad | G3: PRD005 | H3: Bajaj Mixer Grinder 750W | I3: Appliances | J3: 2100 | K3: 17 | L3: 0.06 | M3: 33558 | N3: Debit Card | O3: Pending | P3: 559300 | Q3: 559300 | R3: 35700 | S3: 2142
A4: ORD01262 | B4: 45552 | C4: SP05 | D4: Suresh Pillai | E4: South | F4: Hyderabad | G4: PRD019 | H4: Classmate A4 Notebook 200pg | I4: Stationery | J4: 85 | K4: 20 | L4: 0.03 | M4: 1649 | N4: EMI | O4: Delivered | P4: 54966.667 | Q4: 54966.667 | R4: 1700 | S4: 51
A5: ORD01301 | B5: 45445 | C5: SP011 | D5: Nikhil Joshi | E5: East | F5: Kolkata | G5: PRD008 | H5: American Tourister Trolley | I5: Bags | J5: 4999 | K5: 3 | L5: 0.21 | M5: 11847.63 | N5: Debit Card | O5: Delivered | P5: 56417.286 | Q5: 56417.286 | R5: 14997 | S5: 3149.37
A6: ORD01373 | B6: 45433 | C6: SP011 | D6: Nikhil Joshi | E6: East | F6: Ranchi | G6: PRD010 | H6: Bata Ladies Sandals | I6: Footwear | J6: 1299 | K6: 7 | L6: 0.16 | M6: 7638.12 | N6: Debit Card | O6: Delivered | P6: 47738.25 | Q6: 47738.25 | R6: 9093 | S6: 1454.88
A7: ORD01411 | B7: 45317 | C7: SP07 | D7: Rohit Verma | E7: East | F7: Ranchi | G7: PRD009 | H7: Woodland Men Boots | I7: Footwear | J7: 3499 | K7: 6 | L7: 0.01 | M7: 20784.06 | N7: Credit Card | O7: Delivered | P7: 2078406 | Q7: 2078406 | R7: 20994 | S7: 209.94
A8: ORD01523 | B8: 45592 | C8: SP08 | D8: Kavitha Reddy | E8: West | F8: Ahmedabad | G8: PRD005 | H8: Bajaj Mixer Grinder 750W | I8: Appliances | J8: 2100 | K8: 2 | L8: 0.05 | M8: 3990 | N8: EMI | O8: Delivered | P8: 79800 | Q8: 79800 | R8: 4200 | S8: 210
A9: ORD01674 | B9: 45374 | C9: SP04 | D9: Fatima Sheikh | E9: West | F9: Nagpur | G9: PRD018 | H9: Maggi Noodles Pack of 12 | I9: Food & Bev | J9: 144 | K9: 17 | L9: 0.23 | M9: 1884.96 | N9: EMI | O9: Delivered | P9: 8195.4783 | Q9: 8195.4783 | R9: 2448 | S9: 563.04
A10: ORD01777 | B10: 45623 | C10: SP05 | D10: Suresh Pillai | E10: South | F10: Coimbatore | G10: PRD009 | H10: Woodland Men Boots | I10: Footwear | J10: 3499 | K10: 7 | L10: 0.01 | M10: 24248.07 | N10: Net Banking | O10: Delivered | P10: 2424807 | Q10: 2424807 | R10: 24493 | S10: 244.93
A11: ORD01846 | B11: 45563 | C11: SP010 | D11: Divya Iyer | E11: South | F11: Hyderabad | G11: PRD017 | H11: Tata Gold Tea 500g | I11: Food & Bev | J11: 299 | K11: 8 | L11: 0.23 | M11: 1841.84 | N11: Cash | O11: Delivered | P11: 8008 | Q11: 8008 | R11: 2392 | S11: 550.16
A12: ORD01850 | B12: 45378 | C12: SP07 | D12: Rohit Verma | E12: East | F12: Guwahati | G12: PRD015 | H12: Dettol Liquid Soap 250ml | I12: Personal Care | J12: 145 | K12: 10 | L12: 0.05 | M12: 1377.5 | N12: Debit Card | O12: Returned | P12: 27550 | Q12: 27550 | R12: 1450 | S12: 72.5
A13: ORD01904 | B13: 45619 | C13: SP07 | D13: Rohit Verma | E13: East | F13: Ranchi | G13: PRD009 | H13: Woodland Men Boots | I13: Footwear | J13: 3499 | K13: 20 | L13: 0.15 | M13: 59483 | N13: Cash | O13: Delivered | P13: 396553.33 | Q13: 396553.33 | R13: 69980 | S13: 10497
A14: ORD02130 | B14: 45334 | C14: SP05 | D14: Suresh Pillai | E14: South | F14: Bangalore | G14: PRD019 | H14: Classmate A4 Notebook 200pg | I14: Stationery | J14: 85 | K14: 15 | L14: 0.29 | M14: 905.25 | N14: Debit Card | O14: Delivered | P14: 3121.5517 | Q14: 3121.5517 | R14: 1275 | S14: 369.75
A15: ORD02187 | B15: 45296 | C15: SP03 | D15: Ravi Kumar | E15: East | F15: Guwahati | G15: PRD020 | H15: Cello Butterflow Pens Pk10 | I15: Stationery | J15: 75 | K15: 6 | L15: 0 | M15: 450 | N15: Cash | O15: Cancelled | P15: #DIV/0! | Q15: 0 | R15: 450 | S15: 0
A16: ORD02249 | B16: 45366 | C16: SP04 | D16: Fatima Sheikh | E16: West | F16: Pune | G16: PRD015 | H16: Dettol Liquid Soap 250ml | I16: Personal Care | J16: 145 | K16: 8 | L16: 0.1 | M16: 1044 | N16: Debit Card | O16: Delivered | P16: 10440 | Q16: 10440 | R16: 1160 | S16: 116
A17: ORD02292 | B17: 45455 | C17: SP08 | D17: Kavitha Reddy | E17: West | F17: Pune | G17: PRD011 | H17: Peter England Formal Shirt | I17: Clothing | J17: 1199 | K17: 6 | L17: 0.28 | M17: 5179.68 | N17: Net Banking | O17: Delivered | P17: 18498.857 | Q17: 18498.857 | R17: 7194 | S17: 2014.32
A18: ORD02296 | B18: 45315 | C18: SP07 | D18: Rohit Verma | E18: East | F18: Kolkata | G18: PRD017 | H18: Tata Gold Tea 500g | I18: Food & Bev | J18: 299 | K18: 15 | L18: 0.08 | M18: 4126.2 | N18: EMI | O18: Delivered | P18: 51577.5 | Q18: 51577.5 | R18: 4485 | S18: 358.8
A19: ORD02430 | B19: 45588 | C19: SP09 | D19: Manish Gupta | E19: North | F19: Delhi | G19: PRD011 | H19: Peter England Formal Shirt | I19: Clothing | J19: 1199 | K19: 2 | L19: 0.07 | M19: 2230.14 | N19: Net Banking | O19: Cancelled | P19: 31859.143 | Q19: 31859.143 | R19: 2398 | S19: 167.86
A20: ORD02441 | B20: 45539 | C20: SP09 | D20: Manish Gupta | E20: North | F20: Lucknow | G20: PRD010 | H20: Bata Ladies Sandals | I20: Footwear | J20: 1299 | K20: 8 | L20: 0.16 | M20: 8729.28 | N20: Net Banking | O20: Delivered | P20: 54558 | Q20: 54558 | R20: 10392 | S20: 1662.72
A21: ORD02458 | B21: 45558 | C21: SP04 | D21: Fatima Sheikh | E21: West | F21: Mumbai | G21: PRD002 | H21: iPhone 15 128GB | I21: Electronics | J21: 79999 | K21: 9 | L21: 0.29 | M21: 511193.61 | N21: Credit Card | O21: Delivered | P21: 1762736.6 | Q21: 1762736.6 | R21: 719991 | S21: 208797.39
A22: ORD02499 | B22: 45309 | C22: SP011 | D22: Nikhil Joshi | E22: East | F22: Ranchi | G22: PRD008 | H22: American Tourister Trolley | I22: Bags | J22: 4999 | K22: 1 | L22: 0.09 | M22: 4549.09 | N22: Debit Card | O22: Delivered | P22: 50545.444 | Q22: 50545.444 | R22: 4999 | S22: 449.91
A23: ORD02512 | B23: 45435 | C23: SP07 | D23: Rohit Verma | E23: East | F23: Guwahati | G23: PRD010 | H23: Bata Ladies Sandals | I23: Footwear | J23: 1299 | K23: 14 | L23: 0.03 | M23: 17640.42 | N23: Debit Card | O23: Delivered | P23: 588014 | Q23: 588014 | R23: 18186 | S23: 545.58
A24: ORD02521 | B24: 45324 | C24: SP07 | D24: Rohit Verma | E24: East | F24: Kolkata | G24: PRD005 | H24: Bajaj Mixer Grinder 750W | I24: Appliances | J24: 2100 | K24: 1 | L24: 0.05 | M24: 1995 | N24: Debit Card | O24: Delivered | P24: 39900 | Q24: 39900 | R24: 2100 | S24: 105
A25: ORD02573 | B25: 45620 | C25: SP06 | D25: Anjali Mehta | E25: North | F25: Agra | G25: PRD010 | H25: Bata Ladies Sandals | I25: Footwear | J25: 1299 | K25: 14 | L25: 0.18 | M25: 14912.52 | N25: Debit Card | O25: Delivered | P25: 82847.333 | Q25: 82847.333 | R25: 18186 | S25: 3273.48
A26: ORD02658 | B26: 45649 | C26: SP09 | D26: Manish Gupta | E26: North | F26: Chandigarh | G26: PRD017 | H26: Tata Gold Tea 500g | I26: Food & Bev | J26: 299 | K26: 10 | L26: 0.21 | M26: 2362.1 | N26: Cash | O26: Returned | P26: 11248.095 | Q26: 11248.095 | R26: 2990 | S26: 627.9
A27: ORD02682 | B27: 45511 | C27: SP012 | D27: Sneha Patil | E27: West | F27: Mumbai | G27: PRD006 | H27: Whirlpool 7kg Washing Machine | I27: Appliances | J27: 22000 | K27: 12 | L27: 0.26 | M27: 195360 | N27: Cash | O27: Returned | P27: 751384.62 | Q27: 751384.62 | R27: 264000 | S27: 68640
... A58: ORD01448 | B58: 45436 | C58: SP02 | D58: Priya Nair | E58: South | F58: Kochi | G58: PRD008 | H58: American Tourister Trolley | I58: Bags | J58: 4999 | K58: 5 | L58: 0.09 | M58: 22745.45 | N58: Credit Card | O58: Returned | P58: 252727.22 | Q58: 252727.22 | R58: 24995 | S58: 2249.55
A59: ORD01485 | B59: 45612 | C59: SP06 | D59: Anjali Mehta | E59: North | F59: Delhi | G59: PRD008 | H59: American Tourister Trolley | I59: Bags | J59: 4999 | K59: 1 | L59: 0 | M59: 4999 | N59: Net Banking | O59: Pending | P59: #DIV/0! | Q59: 0 | R59: 4999 | S59: 0
A60: ORD01518 | B60: 45486 | C60: SP07 | D60: Rohit Verma | E60: East | F60: Patna | G60: PRD008 | H60: American Tourister Trolley | I60: Bags | J60: 4999 | K60: 17 | L60: 0.24 | M60: 64587.08 | N60: Cash | O60: Delivered | P60: 269112.83 | Q60: 269112.83 | R60: 84983 | S60: 20395.92
A61: ORD01583 | B61: 45297 | C61: SP09 | D61: Manish Gupta | E61: North | F61: Delhi | G61: PRD008 | H61: American Tourister Trolley | I61: Bags | J61: 4999 | K61: 20 | L61: 0.05 | M61: 94981 | N61: EMI | O61: Delivered | P61: 1899620 | Q61: 1899620 | R61: 99980 | S61: 4999
A62: ORD01586 | B62: 45536 | C62: SP05 | D62: Suresh Pillai | E62: South | F62: Kochi | G62: PRD008 | H62: American Tourister Trolley | I62: Bags | J62: 4999 | K62: 20 | L62: 0.29 | M62: 70985.8 | N62: Net Banking | O62: Pending | P62: 244778.62 | Q62: 244778.62 | R62: 99980 | S62: 28994.2
A63: ORD01589 | B63: 45307 | C63: SP08 | D63: Kavitha Reddy | E63: West | F63: Surat | G63: PRD008 | H63: American Tourister Trolley | I63: Bags | J63: 4999 | K63: 11 | L63: 0.29 | M63: 39042.19 | N63: Net Banking | O63: Delivered | P63: 134628.24 | Q63: 134628.24 | R63: 54989 | S63: 15946.81
A64: ORD01602 | B64: 45387 | C64: SP010 | D64: Divya Iyer | E64: South | F64: Bangalore | G64: PRD008 | H64: American Tourister Trolley | I64: Bags | J64: 4999 | K64: 4 | L64: 0.22 | M64: 15596.88 | N64: Debit Card | O64: Delivered | P64: 70894.909 | Q64: 70894.909 | R64: 19996 | S64: 4399.12
A65: ORD01623 | B65: 45422 | C65: SP07 | D65: Rohit Verma | E65: East | F65: Ranchi | G65: PRD008 | H65: American Tourister Trolley | I65: Bags | J65: 4999 | K65: 17 | L65: 0.23 | M65: 65436.91 | N65: EMI | O65: Cancelled | P65: 284508.3 | Q65: 284508.3 | R65: 84983 | S65: 19546.09
A66: ORD01659 | B66: 45406 | C66: SP04 | D66: Fatima Sheikh | E66: West | F66: Mumbai | G66: PRD008 | H66: American Tourister Trolley | I66: Bags | J66: 4999 | K66: 9 | L66: 0.24 | M66: 34193.16 | N66: Net Banking | O66: Delivered | P66: 142471.5 | Q66: 142471.5 | R66: 44991 | S66: 10797.84
A67: ORD01664 | B67: 45582 | C67: SP09 | D67: Manish Gupta | E67: North | F67: Jaipur | G67: PRD008 | H67: American Tourister Trolley | I67: Bags | J67: 4999 | K67: 5 | L67: 0.02 | M67: 24495.1 | N67: Net Banking | O67: Pending | P67: 1224755 | Q67: 1224755 | R67: 24995 | S67: 499.9
A68: ORD01665 | B68: 45338 | C68: SP02 | D68: Priya Nair | E68: South | F68: Kochi | G68: PRD008 | H68: American Tourister Trolley | I68: Bags | J68: 4999 | K68: 14 | L68: 0.09 | M68: 63687.26 | N68: Credit Card | O68: Delivered | P68: 707636.22 | Q68: 707636.22 | R68: 69986 | S68: 6298.74
A69: ORD01683 | B69: 45606 | C69: SP011 | D69: Nikhil Joshi | E69: East | F69: Bhubaneswar | G69: PRD008 | H69: American Tourister Trolley | I69: Bags | J69: 4999 | K69: 14 | L69: 0.07 | M69: 65086.98 | N69: Credit Card | O69: Delivered | P69: 929814 | Q69: 929814 | R69: 69986 | S69: 4899.02
A70: ORD01693 | B70: 45637 | C70: SP08 | D70: Kavitha Reddy | E70: West | F70: Mumbai | G70: PRD008 | H70: American Tourister Trolley | I70: Bags | J70: 4999 | K70: 14 | L70: 0.12 | M70: 61587.68 | N70: Debit Card | O70: Delivered | P70: 513230.67 | Q70: 513230.67 | R70: 69986 | S70: 8398.32
...

Sheet Pv tables
E2: values to display | R2: Row Labels | S2: Sum of Revenue
A3: Total Orders | B3: Total Revenue | C3: Average Order value | E3: total oders | F3: total revenue | G3: avg order | R3: Ambiguous | S3: 37121.63
A4: 2400 | B4: 1.7732628e+08 | C4: 73885.951 | E4: =TEXT(A4,"#,##") -> 2,400 | F4: =TEXT(B4/10000000,"0.0")&" Cr" -> 17.7 Cr | G4: =TEXT(C4/1000,"0.0")&" k" -> 73.9 k | R4: American Tourister Trolley | S4: 3543041.2
R5: Bajaj Mixer Grinder 750W | S5: 2542701
R6: Bata Ladies Sandals | S6: 1594054.9
R7: Boat Rockerz 450 Headphones | S7: 1955207.2
A8: Row Labels | B8: Sum of Revenue | R8: Cadbury Dairy Milk Silk | S8: 112659.55
A9: Jan | B9: 2769017.6 | R9: Cello Butterflow Pens Pk10 | S9: 88575.75
A10: Feb | B10: 893375.17 | R10: Classmate A4 Notebook 200pg | S10: 86672.8
A11: Mar | B11: 3042153 | R11: Colgate MaxFresh Toothpaste | S11: 99074.55
A12: Apr | B12: 2398970.8 | R12: Dettol Liquid Soap 250ml | S12: 150788.4
A13: May | B13: 4951091.3 | R13: Himalaya Face Wash 150ml | S13: 215236.4
A14: Jun | B14: 3357906.2 | R14: iPhone 15 128GB | S14: 79975800
A15: Jul | B15: 3213561.3 | R15: Levi's 511 Slim Jeans | S15: 2307976.4
A16: Aug | B16: 3514407.8 | R16: Maggi Noodles Pack of 12 | S16: 151848
A17: Sep | B17: 4203497.8 | R17: Peter England Formal Shirt | S17: 1289464.6
A18: Oct | B18: 3698849.5 | I18: Count of Order Status | J18: Column Labels | R18: Prestige Induction Cooktop | S18: 3893344
A19: Nov | B19: 2546192.2 | I19: Row Labels | J19: Cancelled | K19: Returned | L19: Grand Total | R19: Samsung 55" QLED TV | S19: 49117500
A20: Dec | B20: 6104315 | I20: Nikhil Joshi | J20: 18 | K20: 24 | L20: 42 | R20: Tata Gold Tea 500g | S20: 259756.25
A21: Grand Total | B21: 40693338 | I21: Rohit Verma | J21: 27 | K21: 20 | L21: 47 | R21: Whirlpool 7kg Washing Machine | S21: 22676500
I22: Ravi Kumar | J22: 26 | K22: 15 | L22: 41 | R22: Wildcraft 50L Backpack | S22: 2931452
A23: Row Labels | B23: Sum of Revenue | I23: Grand Total | J23: 71 | K23: 59 | L23: 130 | R23: Woodland Men Boots | S23: 4297506.8
A24: Ravi Kumar | B24: 16462377 | R24: Grand Total | S24: 1.7732628e+08
A25: Grand Total | B25: 16462377
A27: north region at top | E27: electronics created most revenue
A28: Row Labels | B28: Sum of Revenue | E28: Row Labels | F28: Sum of Revenue
A29: North | B29: 47982458 | E29: Electronics | F29: 30069938 | I29: Count of Order Status | J29: Column Labels
A30: West | B30: 46721236 | E30: Appliances | F30: 6448011 | I30: Row Labels | J30: Cancelled | K30: Delivered | L30: Pending | M30: Returned | N30: Unknown | O30: Grand Total
A31: South | B31: 41929250 | E31: Footwear | F31: 1711747.3 | I31: Wildcraft 50L Backpack | K31: 25 | L31: 3 | M31: 6 | N31: 1 | O31: 35
A32: East | B32: 40693338 | E32: Bags | F32: 1514337 | I32: Peter England Formal Shirt | J32: 3 | K32: 17 | L32: 6 | M32: 5 | N32: 1 | O32: 32
A33: Grand Total | B33: 1.7732628e+08 | E33: Clothing | F33: 596500.63 | I33: Whirlpool 7kg Washing Machine | J33: 3 | K33: 16 | L33: 1 | M33: 5 | N33: 1 | O33: 26
E34: Grand Total | F34: 40340534 | I34: Bata Ladies Sandals | J34: 4 | K34: 23 | L34: 4 | M34: 5 | N34: 2 | O34: 38
I35: Prestige Induction Cooktop | J35: 1 | K35: 22 | M35: 5 | N35: 1 | O35: 29
A36: Row Labels | B36: Count of Order ID | I36: Classmate A4 Notebook 200pg | J36: 2 | K36: 22 | L36: 2 | M36: 5 | O36: 31
A37: Kavitha Reddy | B37: 219 | I37: Dettol Liquid Soap 250ml | J37: 2 | K37: 17 | L37: 1 | M37: 4 | N37: 1 | O37: 25
A38: Grand Total | B38: 219 | I38: Cello Butterflow Pens Pk10 | J38: 7 | K38: 24 | L38: 5 | M38: 3 | N38: 1 | O38: 40
I39: Tata Gold Tea 500g | J39: 6 | K39: 16 | L39: 3 | M39: 3 | O39: 28
A40: top 5 best selling products | I40: Samsung 55" QLED TV | J40: 2 | K40: 19 | L40: 4 | M40: 3 | N40: 2 | O40: 30
A41: Row Labels | B41: Sum of Revenue | E41: variance of UP per category | I41: Maggi Noodles Pack of 12 | J41: 4 | K41: 23 | L41: 5 | M41: 3 | N41: 1 | O41: 36
A42: iPhone 15 128GB | B42: 79975800 | E42: Row Labels | F42: Sum of Unit Price | I42: Himalaya Face Wash 150ml | J42: 3 | K42: 29 | L42: 4 | M42: 3 | N42: 2 | O42: 41
...

Sheet Dashboard

Sheet Sheet3
